Logged in as
MemeBot
702519705935806516
------
meme called
Logged in as
MemeBot
702519705935806516
------
say called
b'Quim codos el que te rompe los codos'
memesound called
['sonidos/breakfast-down-cut.mp3', 'sonidos/roses meme.mp3', 'sonidos/nandito sin retalllar.mp3', 'sonidos/friendzone song meme.mp3', 'sonidos/are you with me3.mp3', 'sonidos/me han dao por culo dios mio.mp3', 'sonidos/imodaba imodaba ymodaba.mp3', 'sonidos/FCDespacito Feat Valderrrame Teres and Saiz the dickstroyer.mp3', 'sonidos/tengo miedo.mp3', 'sonidos/autistas.mp3', 'sonidos/por favor vegettita.mp3', 'sonidos/si no vevo agua me asfixio.mp3', 'sonidos/ymodaba.mp3', 'sonidos/mira la magia de mi melena.mp3', 'sonidos/la ruina va a venir-cut.mp3', 'sonidos/expropiese.mp3', 'sonidos/esto es una catastrofe.mp3', 'sonidos/y mucho mas.mp3', 'sonidos/orslok karmaland.mp3', 'sonidos/hey woman.mp3', 'sonidos/ai yo que sey.mp3', 'sonidos/el froturo.mp3', 'sonidos/que calvario dios mio ignatius mi situacion ahora bruno.mp3', 'sonidos/le corto el cuello.mp3', 'sonidos/I love refrigerators.mp3']
done playing sound
meme called
222403160
{'success': True, 'data': {'url': 'https://i.imgflip.com/43ih2l.jpg', 'page_url': 'https://imgflip.com/i/43ih2l'}}
meme called
meme called
71428573
{'success': True, 'data': {'url': 'https://i.imgflip.com/43ih5w.jpg', 'page_url': 'https://imgflip.com/i/43ih5w'}}
meme called
181913649
{'success': True, 'data': {'url': 'https://i.imgflip.com/43iha4.jpg', 'page_url': 'https://imgflip.com/i/43iha4'}}
say called
b'hola chicos soy laia saumell, ya os voy anunciando que soy una trolasa y todo esto era una prueba para ver que subnormales sois y caer en la trampa. Ya os voy anunciando que un 0 para todos y que me chupeis el orto bien fuerte por subnormales. Con cari\xc3\xb1o,Laia'
say called
b'tengo miedo'
say called
b'quim codos el que habla por los codos'
memesound called
['sonidos/breakfast-down-cut.mp3', 'sonidos/roses meme.mp3', 'sonidos/nandito sin retalllar.mp3', 'sonidos/friendzone song meme.mp3', 'sonidos/are you with me3.mp3', 'sonidos/me han dao por culo dios mio.mp3', 'sonidos/imodaba imodaba ymodaba.mp3', 'sonidos/FCDespacito Feat Valderrrame Teres and Saiz the dickstroyer.mp3', 'sonidos/tengo miedo.mp3', 'sonidos/autistas.mp3', 'sonidos/por favor vegettita.mp3', 'sonidos/si no vevo agua me asfixio.mp3', 'sonidos/ymodaba.mp3', 'sonidos/mira la magia de mi melena.mp3', 'sonidos/la ruina va a venir-cut.mp3', 'sonidos/expropiese.mp3', 'sonidos/esto es una catastrofe.mp3', 'sonidos/y mucho mas.mp3', 'sonidos/orslok karmaland.mp3', 'sonidos/hey woman.mp3', 'sonidos/ai yo que sey.mp3', 'sonidos/el froturo.mp3', 'sonidos/que calvario dios mio ignatius mi situacion ahora bruno.mp3', 'sonidos/le corto el cuello.mp3', 'sonidos/I love refrigerators.mp3']
done playing sound
say called
b'quim codina quim codillo quim codos quim condena quim caudillo quim cortina'
say called
b'quim couldina , para el dolor de cabeza'
meme called
101470
{'success': True, 'data': {'url': 'https://i.imgflip.com/43z22u.jpg', 'page_url': 'https://imgflip.com/i/43z22u'}}
meme called
438680
{'success': True, 'data': {'url': 'https://i.imgflip.com/43z24o.jpg', 'page_url': 'https://imgflip.com/i/43z24o'}}
meme called
4173692
{'success': True, 'data': {'url': 'https://i.imgflip.com/43z24x.jpg', 'page_url': 'https://imgflip.com/i/43z24x'}}
meme called
89655
{'success': True, 'data': {'url': 'https://i.imgflip.com/43z27p.jpg', 'page_url': 'https://imgflip.com/i/43z27p'}}
say called
b'barto vargas el terror del eixample'
say called
b'hola a todos hijos de puta, soy Laia Saumell, que sepais que nos hemos dado cuenta de que el segundo parcial estaba abierto, hemos hecho un experimento social para comprobar si os copiais, y efectivamente hemos dado en el clavo, por lo tanto estais todos suspendidos y me vais a comer el co\xc3\xb1o todos, i lof yu artur nicolau'
say called
b'bartolomeo bartomeu vergas vergalarga'
say called
b'Bronu Mayo la mejor empresa de gafas VR'
say called
b'bronu mayo el hombre del infierno'
meme called
161865971
{'success': True, 'data': {'url': 'https://i.imgflip.com/43zepl.jpg', 'page_url': 'https://imgflip.com/i/43zepl'}}
memesound called
['sonidos/breakfast-down-cut.mp3', 'sonidos/roses meme.mp3', 'sonidos/nandito sin retalllar.mp3', 'sonidos/friendzone song meme.mp3', 'sonidos/are you with me3.mp3', 'sonidos/me han dao por culo dios mio.mp3', 'sonidos/imodaba imodaba ymodaba.mp3', 'sonidos/FCDespacito Feat Valderrrame Teres and Saiz the dickstroyer.mp3', 'sonidos/tengo miedo.mp3', 'sonidos/autistas.mp3', 'sonidos/por favor vegettita.mp3', 'sonidos/si no vevo agua me asfixio.mp3', 'sonidos/ymodaba.mp3', 'sonidos/mira la magia de mi melena.mp3', 'sonidos/la ruina va a venir-cut.mp3', 'sonidos/expropiese.mp3', 'sonidos/esto es una catastrofe.mp3', 'sonidos/y mucho mas.mp3', 'sonidos/orslok karmaland.mp3', 'sonidos/hey woman.mp3', 'sonidos/ai yo que sey.mp3', 'sonidos/el froturo.mp3', 'sonidos/que calvario dios mio ignatius mi situacion ahora bruno.mp3', 'sonidos/le corto el cuello.mp3', 'sonidos/I love refrigerators.mp3']
done playing sound
meme called
61582
{'success': True, 'data': {'url': 'https://i.imgflip.com/43zgbi.jpg', 'page_url': 'https://imgflip.com/i/43zgbi'}}
meme called
195389
{'success': True, 'data': {'url': 'https://i.imgflip.com/43zgcg.jpg', 'page_url': 'https://imgflip.com/i/43zgcg'}}
say called
b'Joder la Mercedes Mil\xc3\xa1, alias brandi que me dijo que a las 12 le iba bien, ahora me dijo que no ,que me avisar\xc3\xada, ha pasado mucho tiempo y no me ha respondido me cago en la puta'
say called
b'puto Joan bartrina que solo vende trina le envi\xc3\xa9 un mensaje hace mil a\xc3\xb1os, el cabr\xc3\xb3n no me ha respondido me cago en la puta iuuuuuu,esto es una catastrofe'
say called
b'Quim codos el que te da codazos mientras habla'
say called
b'Quim cortinas el que se enrolla hablando como una cortina'
say called
b'He de arreglar aix\xc3\xb2 jajajajaj confon un missatge normal amb una comanda al bot'
say called
say called
b"F examen d'ahir"
Class initialized
Logged in as
MemeBot
702519705935806516
------
Ignoring exception in on_message
Traceback (most recent call last):
  File "/usr/local/lib/python3.5/dist-packages/discord/ext/commands/core.py", line 83, in wrapped
    ret = await coro(*args, **kwargs)
  File "bot.py", line 60, in say
    await loquendo_interact(args,ctx.message.channel,False)
  File "/root/discord-bot/loquendo_api_tss.py", line 28, in loquendo_interact
    tts_segment = loquendo_tts(str(finalMessage), lang)
  File "/root/discord-bot/tts.py", line 17, in loquendo_tts
    return overlay_sound_perfect_loop(tts(text, lang), overlaid_audio)
  File "/root/discord-bot/tts.py", line 9, in tts
    tts_object = gTTS(text, lang=lang)
  File "/usr/local/lib/python3.5/dist-packages/gtts/tts.py", line 131, in __init__
    raise ValueError("Language not supported: %s" % lang)
ValueError: Language not supported: a

The above exception was the direct cause of the following exception:

Traceback (most recent call last):
  File "/usr/local/lib/python3.5/dist-packages/discord/client.py", line 312, in _run_event
    await coro(*args, **kwargs)
  File "/usr/local/lib/python3.5/dist-packages/discord/ext/commands/bot.py", line 930, in on_message
    await self.process_commands(message)
  File "/usr/local/lib/python3.5/dist-packages/discord/ext/commands/bot.py", line 927, in process_commands
    await self.invoke(ctx)
  File "/usr/local/lib/python3.5/dist-packages/discord/ext/commands/bot.py", line 894, in invoke
    await ctx.command.dispatch_error(ctx, exc)
  File "/usr/local/lib/python3.5/dist-packages/discord/ext/commands/core.py", line 398, in dispatch_error
    await injected(ctx, error)
  File "/usr/local/lib/python3.5/dist-packages/discord/ext/commands/core.py", line 69, in wrapped
    ret = await coro(*args, **kwargs)
  File "bot.py", line 68, in say_error
    raise error
  File "/usr/local/lib/python3.5/dist-packages/discord/ext/commands/bot.py", line 892, in invoke
    await ctx.command.invoke(ctx)
  File "/usr/local/lib/python3.5/dist-packages/discord/ext/commands/core.py", line 797, in invoke
    await injected(*ctx.args, **ctx.kwargs)
  File "/usr/local/lib/python3.5/dist-packages/discord/ext/commands/core.py", line 92, in wrapped
    raise CommandInvokeError(exc) from exc
discord.ext.commands.errors.CommandInvokeError: Command raised an exception: ValueError: Language not supported: a
Ignoring exception in on_message
Traceback (most recent call last):
  File "/usr/local/lib/python3.5/dist-packages/discord/ext/commands/core.py", line 83, in wrapped
    ret = await coro(*args, **kwargs)
  File "bot.py", line 60, in say
    await loquendo_interact(args,ctx.message.channel,False)
  File "/root/discord-bot/loquendo_api_tss.py", line 28, in loquendo_interact
    tts_segment = loquendo_tts(str(finalMessage), lang)
  File "/root/discord-bot/tts.py", line 17, in loquendo_tts
    return overlay_sound_perfect_loop(tts(text, lang), overlaid_audio)
  File "/root/discord-bot/tts.py", line 9, in tts
    tts_object = gTTS(text, lang=lang)
  File "/usr/local/lib/python3.5/dist-packages/gtts/tts.py", line 131, in __init__
    raise ValueError("Language not supported: %s" % lang)
ValueError: Language not supported: a

The above exception was the direct cause of the following exception:

Traceback (most recent call last):
  File "/usr/local/lib/python3.5/dist-packages/discord/client.py", line 312, in _run_event
    await coro(*args, **kwargs)
  File "/usr/local/lib/python3.5/dist-packages/discord/ext/commands/bot.py", line 930, in on_message
    await self.process_commands(message)
  File "/usr/local/lib/python3.5/dist-packages/discord/ext/commands/bot.py", line 927, in process_commands
    await self.invoke(ctx)
  File "/usr/local/lib/python3.5/dist-packages/discord/ext/commands/bot.py", line 894, in invoke
    await ctx.command.dispatch_error(ctx, exc)
  File "/usr/local/lib/python3.5/dist-packages/discord/ext/commands/core.py", line 398, in dispatch_error
    await injected(ctx, error)
  File "/usr/local/lib/python3.5/dist-packages/discord/ext/commands/core.py", line 69, in wrapped
    ret = await coro(*args, **kwargs)
  File "bot.py", line 68, in say_error
    raise error
  File "/usr/local/lib/python3.5/dist-packages/discord/ext/commands/bot.py", line 892, in invoke
    await ctx.command.invoke(ctx)
  File "/usr/local/lib/python3.5/dist-packages/discord/ext/commands/core.py", line 797, in invoke
    await injected(*ctx.args, **ctx.kwargs)
  File "/usr/local/lib/python3.5/dist-packages/discord/ext/commands/core.py", line 92, in wrapped
    raise CommandInvokeError(exc) from exc
discord.ext.commands.errors.CommandInvokeError: Command raised an exception: ValueError: Language not supported: a
Ignoring exception in on_message
Traceback (most recent call last):
  File "/usr/local/lib/python3.5/dist-packages/discord/ext/commands/core.py", line 83, in wrapped
    ret = await coro(*args, **kwargs)
  File "bot.py", line 60, in say
    await loquendo_interact(args,ctx.message.channel,False)
  File "/root/discord-bot/loquendo_api_tss.py", line 28, in loquendo_interact
    tts_segment = loquendo_tts(str(finalMessage), lang)
  File "/root/discord-bot/tts.py", line 17, in loquendo_tts
    return overlay_sound_perfect_loop(tts(text, lang), overlaid_audio)
  File "/root/discord-bot/tts.py", line 9, in tts
    tts_object = gTTS(text, lang=lang)
  File "/usr/local/lib/python3.5/dist-packages/gtts/tts.py", line 131, in __init__
    raise ValueError("Language not supported: %s" % lang)
ValueError: Language not supported: a

The above exception was the direct cause of the following exception:

Traceback (most recent call last):
  File "/usr/local/lib/python3.5/dist-packages/discord/client.py", line 312, in _run_event
    await coro(*args, **kwargs)
  File "/usr/local/lib/python3.5/dist-packages/discord/ext/commands/bot.py", line 930, in on_message
    await self.process_commands(message)
  File "/usr/local/lib/python3.5/dist-packages/discord/ext/commands/bot.py", line 927, in process_commands
    await self.invoke(ctx)
  File "/usr/local/lib/python3.5/dist-packages/discord/ext/commands/bot.py", line 894, in invoke
    await ctx.command.dispatch_error(ctx, exc)
  File "/usr/local/lib/python3.5/dist-packages/discord/ext/commands/core.py", line 398, in dispatch_error
    await injected(ctx, error)
  File "/usr/local/lib/python3.5/dist-packages/discord/ext/commands/core.py", line 69, in wrapped
    ret = await coro(*args, **kwargs)
  File "bot.py", line 68, in say_error
    raise error
  File "/usr/local/lib/python3.5/dist-packages/discord/ext/commands/bot.py", line 892, in invoke
    await ctx.command.invoke(ctx)
  File "/usr/local/lib/python3.5/dist-packages/discord/ext/commands/core.py", line 797, in invoke
    await injected(*ctx.args, **ctx.kwargs)
  File "/usr/local/lib/python3.5/dist-packages/discord/ext/commands/core.py", line 92, in wrapped
    raise CommandInvokeError(exc) from exc
discord.ext.commands.errors.CommandInvokeError: Command raised an exception: ValueError: Language not supported: a
Class initialized
Logged in as
MemeBot
702519705935806516
------
say called
b'mp mucha polls'
tiktok called
yomama called
genius called
say called
b'hola'
genius called
Searching for "The box"...
Done.
Song lenght 2669
LOQUENDO A SONG
say called
b'hola a todos, me llamo Laia Saumell, ya habeis podido comprobar que estais todos aprobados, enhorabuena a todo el mundo, os amo os follo, ahora ya no tenei excusa para poder insultar a este bellezon, adios y hasta siempre, no os quiero volver a ver por los pasillos hijos de puta'
say called
b'hola a todos, me llamo Laia Saumell, ya habeis podido comprobar que estais todos aprobados, enhorabuena a todo el mundo, os amo os follo, ahora ya no tenei excusa para poder insultar a este bellezon, adios y hasta siempre, no os quiero volver a ver por los pasillos hijos de puta'
say called
b'quim codos el que te huele los codos'
say called
b'hola a todos, me llamo Laia Saumell, ya habeis podido comprobar que estais todos aprobados, enhorabuena a todo el mundo, os amo os follo, ahora ya no tenei excusa para poder insultar a este bellezon, adios y hasta siempre, no os quiero volver a ver por los pasillos hijos de puta'
say called
b'hola a todos, me llamo Laia Saumell, ya habeis podido comprobar que estais todos aprobados, enhorabuena a todo el mundo, os amo os follo, ahora ya no tenei excusa para poder insultar a este bellezon, adios y hasta siempre, no os quiero volver a ver por los pasillos hijos de puta'
genius called
Searching for "The box"...
Done.
Song lenght 2669
LOQUENDO A SONG
genius called
Searching for "bohemian rhapsody"...
Done.
Song lenght 1972
LOQUENDO A SONG
say called
b'No se, porque mi ruoloj esta rota'
say called
b'Puto elver galarga que no sabe utilizar el discord'
say called
b'gemma seda la que te seda'
say called
b'NO LOSE, POR QUE MI REULOUJ ESTA ROTA'
say called
b'NO LOSE, POR QUE MI REULOUJ ESTA ROTA'
say called
b'SOM TOTS DE LA UAB'
say called
b'som tots de la uab'
say called
b'no lose, por que mi reulouj esta rota'
Ignoring exception in on_message
Traceback (most recent call last):
  File "/usr/local/lib/python3.5/dist-packages/discord/ext/commands/core.py", line 83, in wrapped
    ret = await coro(*args, **kwargs)
  File "bot.py", line 60, in say
    await loquendo_interact(args,bot,ctx,ctx.message.channel,False)
  File "/root/discord-bot/loquendo_api_tss.py", line 37, in loquendo_interact
    channel = user.voice.channel
AttributeError: 'NoneType' object has no attribute 'channel'

The above exception was the direct cause of the following exception:

Traceback (most recent call last):
  File "/usr/local/lib/python3.5/dist-packages/discord/client.py", line 312, in _run_event
    await coro(*args, **kwargs)
  File "/usr/local/lib/python3.5/dist-packages/discord/ext/commands/bot.py", line 930, in on_message
    await self.process_commands(message)
  File "/usr/local/lib/python3.5/dist-packages/discord/ext/commands/bot.py", line 927, in process_commands
    await self.invoke(ctx)
  File "/usr/local/lib/python3.5/dist-packages/discord/ext/commands/bot.py", line 894, in invoke
    await ctx.command.dispatch_error(ctx, exc)
  File "/usr/local/lib/python3.5/dist-packages/discord/ext/commands/core.py", line 398, in dispatch_error
    await injected(ctx, error)
  File "/usr/local/lib/python3.5/dist-packages/discord/ext/commands/core.py", line 69, in wrapped
    ret = await coro(*args, **kwargs)
  File "bot.py", line 68, in say_error
    raise error
  File "/usr/local/lib/python3.5/dist-packages/discord/ext/commands/bot.py", line 892, in invoke
    await ctx.command.invoke(ctx)
  File "/usr/local/lib/python3.5/dist-packages/discord/ext/commands/core.py", line 797, in invoke
    await injected(*ctx.args, **ctx.kwargs)
  File "/usr/local/lib/python3.5/dist-packages/discord/ext/commands/core.py", line 92, in wrapped
    raise CommandInvokeError(exc) from exc
discord.ext.commands.errors.CommandInvokeError: Command raised an exception: AttributeError: 'NoneType' object has no attribute 'channel'
Ignoring exception in on_message
Traceback (most recent call last):
  File "/usr/local/lib/python3.5/dist-packages/discord/ext/commands/core.py", line 83, in wrapped
    ret = await coro(*args, **kwargs)
  File "bot.py", line 60, in say
    await loquendo_interact(args,bot,ctx,ctx.message.channel,False)
  File "/root/discord-bot/loquendo_api_tss.py", line 37, in loquendo_interact
    channel = user.voice.channel
AttributeError: 'NoneType' object has no attribute 'channel'

The above exception was the direct cause of the following exception:

Traceback (most recent call last):
  File "/usr/local/lib/python3.5/dist-packages/discord/client.py", line 312, in _run_event
    await coro(*args, **kwargs)
  File "/usr/local/lib/python3.5/dist-packages/discord/ext/commands/bot.py", line 930, in on_message
    await self.process_commands(message)
  File "/usr/local/lib/python3.5/dist-packages/discord/ext/commands/bot.py", line 927, in process_commands
    await self.invoke(ctx)
  File "/usr/local/lib/python3.5/dist-packages/discord/ext/commands/bot.py", line 894, in invoke
    await ctx.command.dispatch_error(ctx, exc)
  File "/usr/local/lib/python3.5/dist-packages/discord/ext/commands/core.py", line 398, in dispatch_error
    await injected(ctx, error)
  File "/usr/local/lib/python3.5/dist-packages/discord/ext/commands/core.py", line 69, in wrapped
    ret = await coro(*args, **kwargs)
  File "bot.py", line 68, in say_error
    raise error
  File "/usr/local/lib/python3.5/dist-packages/discord/ext/commands/bot.py", line 892, in invoke
    await ctx.command.invoke(ctx)
  File "/usr/local/lib/python3.5/dist-packages/discord/ext/commands/core.py", line 797, in invoke
    await injected(*ctx.args, **ctx.kwargs)
  File "/usr/local/lib/python3.5/dist-packages/discord/ext/commands/core.py", line 92, in wrapped
    raise CommandInvokeError(exc) from exc
discord.ext.commands.errors.CommandInvokeError: Command raised an exception: AttributeError: 'NoneType' object has no attribute 'channel'
Class initialized
Logged in as
MemeBot
702519705935806516
------
say called
b'martinosky osky despierta y deja el porro martinosky osky'
say called
b'brunosky0012'
